Ms: 80 | Mt: 20 | dcm: 1.00 | layer: 2 | Epoch: 1/5
Accuracy of the mnist dataset: 0.519900
Accuracy of the mnist_m dataset: 0.092656
Ms: 80 | Mt: 20 | dcm: 1.00 | layer: 2 | Epoch: 2/5
Accuracy of the mnist dataset: 0.636600
Exception ignored in: <function _releaseLock at 0x7fb1140b13a0>
Traceback (most recent call last):
  File "/home/huseyin/anaconda3/envs/dannpy5/lib/python3.8/logging/__init__.py", line 223, in _releaseLock
    def _releaseLock():
KeyboardInterrupt:
Traceback (most recent call last):
  File "/home/huseyin/anaconda3/envs/dannpy5/lib/python3.8/site-packages/torch/utils/data/dataloader.py", line 779, in _try_get_data
    data = self._data_queue.get(timeout=timeout)
  File "/home/huseyin/anaconda3/envs/dannpy5/lib/python3.8/multiprocessing/queues.py", line 108, in get
    raise Empty
_queue.Empty
During handling of the above exception, another exception occurred:
Traceback (most recent call last):
  File "main.py", line 308, in <module>
    accu_t = test(target_dataset_name)
  File "/home/huseyin/fungtion/dannpy_yeniden/DANN_py3/test.py", line 77, in test
    data_target = data_target_iter.next()
  File "/home/huseyin/anaconda3/envs/dannpy5/lib/python3.8/site-packages/torch/utils/data/dataloader.py", line 363, in __next__
    data = self._next_data()
  File "/home/huseyin/anaconda3/envs/dannpy5/lib/python3.8/site-packages/torch/utils/data/dataloader.py", line 974, in _next_data
    idx, data = self._get_data()
  File "/home/huseyin/anaconda3/envs/dannpy5/lib/python3.8/site-packages/torch/utils/data/dataloader.py", line 941, in _get_data
    success, data = self._try_get_data()
  File "/home/huseyin/anaconda3/envs/dannpy5/lib/python3.8/site-packages/torch/utils/data/dataloader.py", line 792, in _try_get_data
    raise RuntimeError('DataLoader worker (pid(s) {}) exited unexpectedly'.format(pids_str))
RuntimeError: DataLoader worker (pid(s) 18578) exited unexpectedly