2024-03-13 00:05:43,989 INFO    StreamThr :2550 [internal.py:wandb_internal():86] W&B internal server running at pid: 2550, started at: 2024-03-13 00:05:43.988558
2024-03-13 00:05:43,990 DEBUG   HandlerThread:2550 [handler.py:handle_request():146] handle_request: status
2024-03-13 00:05:43,991 INFO    WriterThread:2550 [datastore.py:open_for_write():85] open: /home/huseyin/fungtion/dannpy_yeniden/DANN_py3/wandb/run-20240313_000543-tirrr1qg/run-tirrr1qg.wandb
2024-03-13 00:05:43,993 DEBUG   SenderThread:2550 [sender.py:send():380] send: header
2024-03-13 00:05:43,999 DEBUG   SenderThread:2550 [sender.py:send():380] send: run
2024-03-13 00:05:44,573 INFO    SenderThread:2550 [dir_watcher.py:__init__():211] watching files in: /home/huseyin/fungtion/dannpy_yeniden/DANN_py3/wandb/run-20240313_000543-tirrr1qg/files
2024-03-13 00:05:44,573 INFO    SenderThread:2550 [sender.py:_start_run_threads():1122] run started: tirrr1qg with start time 1710277543.987876
2024-03-13 00:05:44,588 DEBUG   HandlerThread:2550 [handler.py:handle_request():146] handle_request: check_version
2024-03-13 00:05:44,588 DEBUG   SenderThread:2550 [sender.py:send_request():407] send_request: check_version
2024-03-13 00:05:44,831 DEBUG   HandlerThread:2550 [handler.py:handle_request():146] handle_request: run_start
2024-03-13 00:05:44,834 DEBUG   HandlerThread:2550 [system_info.py:__init__():32] System info init
2024-03-13 00:05:44,834 DEBUG   HandlerThread:2550 [system_info.py:__init__():47] System info init done
2024-03-13 00:05:44,834 INFO    HandlerThread:2550 [system_monitor.py:start():194] Starting system monitor
2024-03-13 00:05:44,834 INFO    SystemMonitor:2550 [system_monitor.py:_start():158] Starting system asset monitoring threads
2024-03-13 00:05:44,835 INFO    HandlerThread:2550 [system_monitor.py:probe():214] Collecting system info
2024-03-13 00:05:44,836 INFO    SystemMonitor:2550 [interfaces.py:start():190] Started cpu monitoring
2024-03-13 00:05:44,837 INFO    SystemMonitor:2550 [interfaces.py:start():190] Started disk monitoring
2024-03-13 00:05:44,838 INFO    SystemMonitor:2550 [interfaces.py:start():190] Started gpu monitoring
2024-03-13 00:05:44,839 INFO    SystemMonitor:2550 [interfaces.py:start():190] Started memory monitoring
2024-03-13 00:05:44,840 INFO    SystemMonitor:2550 [interfaces.py:start():190] Started network monitoring
2024-03-13 00:05:44,844 ERROR   gpu       :2550 [interfaces.py:monitor():144] Failed to sample metric: Not Supported
2024-03-13 00:05:44,844 ERROR   gpu       :2550 [interfaces.py:monitor():144] Failed to sample metric: Not Supported
2024-03-13 00:05:44,869 DEBUG   HandlerThread:2550 [system_info.py:probe():196] Probing system
2024-03-13 00:05:44,878 DEBUG   HandlerThread:2550 [system_info.py:_probe_git():181] Probing git
2024-03-13 00:05:44,898 DEBUG   HandlerThread:2550 [system_info.py:_probe_git():189] Probing git done
2024-03-13 00:05:44,898 DEBUG   HandlerThread:2550 [system_info.py:probe():244] Probing system done
2024-03-13 00:05:44,899 DEBUG   HandlerThread:2550 [system_monitor.py:probe():223] {'os': 'Linux-4.15.0-213-generic-x86_64-with-glibc2.10', 'python': '3.8.5', 'heartbeatAt': '2024-03-12T21:05:44.870034', 'startedAt': '2024-03-12T21:05:43.982703', 'docker': None, 'cuda': '10.2.89', 'args': ('-ll', '2', '-Mss', '40', '-e', '300', '-pn', 'dimchange2', '-bs', '128', '-ns', '0.1', '-n', 'yeni Ms ve Mt tatbik edildi. errorlar averaged, sıfırlanması önlendi.', '-r', '3', '-Mt', '40', '-dcms', '10', '0.016'), 'state': 'running', 'program': 'main.py', 'codePathLocal': 'main.py', 'codePath': 'main.py', 'git': {'remote': 'https://github.com/huseyin-karaca/DANN_py3.git', 'commit': '75ac58b31eebf372ca215490a52bbaef6e673ce7'}, 'email': 'huseyinkaraccca@gmail.com', 'root': '/home/huseyin/fungtion/dannpy_yeniden/DANN_py3', 'host': 'elif', 'username': 'huseyin', 'executable': '/home/huseyin/anaconda3/envs/dannpy5/bin/python', 'cpu_count': 4, 'cpu_count_logical': 8, 'cpu_freq': {'current': 2361.66075, 'min': 800.0, 'max': 4100.0}, 'cpu_freq_per_core': [{'current': 2112.061, 'min': 800.0, 'max': 4100.0}, {'current': 2844.028, 'min': 800.0, 'max': 4100.0}, {'current': 2478.232, 'min': 800.0, 'max': 4100.0}, {'current': 1965.477, 'min': 800.0, 'max': 4100.0}, {'current': 2272.87, 'min': 800.0, 'max': 4100.0}, {'current': 2836.255, 'min': 800.0, 'max': 4100.0}, {'current': 2207.117, 'min': 800.0, 'max': 4100.0}, {'current': 2177.246, 'min': 800.0, 'max': 4100.0}], 'disk': {'/': {'total': 467.8886032104492, 'used': 257.2606506347656}}, 'gpu': 'Quadro P600', 'gpu_count': 1, 'gpu_devices': [{'name': 'Quadro P600', 'memory_total': 2097479680}], 'memory': {'total': 15.558303833007812}}
2024-03-13 00:05:44,899 INFO    HandlerThread:2550 [system_monitor.py:probe():224] Finished collecting system info
2024-03-13 00:05:44,899 INFO    HandlerThread:2550 [system_monitor.py:probe():227] Publishing system info
2024-03-13 00:05:44,899 DEBUG   HandlerThread:2550 [system_info.py:_save_pip():52] Saving list of pip packages installed into the current environment
2024-03-13 00:05:44,900 DEBUG   HandlerThread:2550 [system_info.py:_save_pip():68] Saving pip packages done
2024-03-13 00:05:44,900 DEBUG   HandlerThread:2550 [system_info.py:_save_conda():75] Saving list of conda packages installed into the current environment
2024-03-13 00:05:45,576 INFO    Thread-12 :2550 [dir_watcher.py:_on_file_created():271] file/dir created: /home/huseyin/fungtion/dannpy_yeniden/DANN_py3/wandb/run-20240313_000543-tirrr1qg/files/requirements.txt
2024-03-13 00:05:45,576 INFO    Thread-12 :2550 [dir_watcher.py:_on_file_created():271] file/dir created: /home/huseyin/fungtion/dannpy_yeniden/DANN_py3/wandb/run-20240313_000543-tirrr1qg/files/conda-environment.yaml
2024-03-13 00:05:46,845 ERROR   gpu       :2550 [interfaces.py:monitor():144] Failed to sample metric: Not Supported
2024-03-13 00:05:46,845 ERROR   gpu       :2550 [interfaces.py:monitor():144] Failed to sample metric: Not Supported
2024-03-13 00:05:48,090 DEBUG   HandlerThread:2550 [system_info.py:_save_conda():87] Saving conda packages done
2024-03-13 00:05:48,090 DEBUG   HandlerThread:2550 [system_info.py:_save_code():90] Saving code
2024-03-13 00:05:48,094 DEBUG   HandlerThread:2550 [system_info.py:_save_code():111] Saving code done
2024-03-13 00:05:48,094 DEBUG   HandlerThread:2550 [system_info.py:_save_patches():128] Saving git patches
2024-03-13 00:05:48,131 DEBUG   HandlerThread:2550 [system_info.py:_save_patches():170] Saving git patches done
2024-03-13 00:05:48,132 INFO    HandlerThread:2550 [system_monitor.py:probe():229] Finished publishing system info
2024-03-13 00:05:48,138 DEBUG   SenderThread:2550 [sender.py:send():380] send: files
2024-03-13 00:05:48,138 INFO    SenderThread:2550 [sender.py:_save_file():1378] saving file wandb-metadata.json with policy now
2024-03-13 00:05:48,139 INFO    SenderThread:2550 [sender.py:_save_file():1378] saving file code/main.py with policy now
2024-03-13 00:05:48,139 INFO    SenderThread:2550 [sender.py:_save_file():1378] saving file diff.patch with policy now
2024-03-13 00:05:48,148 DEBUG   SenderThread:2550 [sender.py:send():380] send: telemetry
2024-03-13 00:05:48,152 DEBUG   HandlerThread:2550 [handler.py:handle_request():146] handle_request: stop_status
2024-03-13 00:05:48,153 DEBUG   SenderThread:2550 [sender.py:send_request():407] send_request: stop_status
2024-03-13 00:05:48,193 DEBUG   HandlerThread:2550 [handler.py:handle_request():146] handle_request: internal_messages
2024-03-13 00:05:48,574 INFO    Thread-12 :2550 [dir_watcher.py:_on_file_modified():288] file/dir modified: /home/huseyin/fungtion/dannpy_yeniden/DANN_py3/wandb/run-20240313_000543-tirrr1qg/files/conda-environment.yaml
2024-03-13 00:05:48,575 INFO    Thread-12 :2550 [dir_watcher.py:_on_file_created():271] file/dir created: /home/huseyin/fungtion/dannpy_yeniden/DANN_py3/wandb/run-20240313_000543-tirrr1qg/files/wandb-metadata.json
2024-03-13 00:05:48,575 INFO    Thread-12 :2550 [dir_watcher.py:_on_file_created():271] file/dir created: /home/huseyin/fungtion/dannpy_yeniden/DANN_py3/wandb/run-20240313_000543-tirrr1qg/files/diff.patch
2024-03-13 00:05:48,575 INFO    Thread-12 :2550 [dir_watcher.py:_on_file_created():271] file/dir created: /home/huseyin/fungtion/dannpy_yeniden/DANN_py3/wandb/run-20240313_000543-tirrr1qg/files/code/main.py
2024-03-13 00:05:48,575 INFO    Thread-12 :2550 [dir_watcher.py:_on_file_created():271] file/dir created: /home/huseyin/fungtion/dannpy_yeniden/DANN_py3/wandb/run-20240313_000543-tirrr1qg/files/code
2024-03-13 00:05:48,845 ERROR   gpu       :2550 [interfaces.py:monitor():144] Failed to sample metric: Not Supported
2024-03-13 00:05:48,846 ERROR   gpu       :2550 [interfaces.py:monitor():144] Failed to sample metric: Not Supported
2024-03-13 00:05:48,871 INFO    wandb-upload_0:2550 [upload_job.py:push():131] Uploaded file /tmp/tmplmihdiv0wandb/wcuzknhj-wandb-metadata.json
2024-03-13 00:05:48,921 INFO    wandb-upload_1:2550 [upload_job.py:push():131] Uploaded file /tmp/tmplmihdiv0wandb/io4898fx-code/main.py
2024-03-13 00:05:48,978 INFO    wandb-upload_2:2550 [upload_job.py:push():131] Uploaded file /tmp/tmplmihdiv0wandb/0qorkb1k-diff.patch
2024-03-13 00:05:49,458 DEBUG   HandlerThread:2550 [handler.py:handle_request():146] handle_request: status_report
2024-03-13 00:05:50,009 DEBUG   HandlerThread:2550 [handler.py:handle_request():146] handle_request: log_artifact
2024-03-13 00:05:50,010 DEBUG   SenderThread:2550 [sender.py:send_request():407] send_request: log_artifact
2024-03-13 00:05:50,542 INFO    SenderThread:2550 [sender.py:send_request_log_artifact():1444] logged artifact source-dimchange2-main.py - {'id': 'QXJ0aWZhY3Q6NzQ5OTYzNzI5', 'state': 'COMMITTED', 'artifactSequence': {'id': 'QXJ0aWZhY3RDb2xsZWN0aW9uOjE0NzM1ODE4OQ==', 'latestArtifact': {'id': 'QXJ0aWZhY3Q6NzQ5OTYzNzI5', 'versionIndex': 0}}}
2024-03-13 00:05:50,846 ERROR   gpu       :2550 [interfaces.py:monitor():144] Failed to sample metric: Not Supported
2024-03-13 00:05:50,846 ERROR   gpu       :2550 [interfaces.py:monitor():144] Failed to sample metric: Not Supported
2024-03-13 00:05:52,847 ERROR   gpu       :2550 [interfaces.py:monitor():144] Failed to sample metric: Not Supported
2024-03-13 00:05:52,847 ERROR   gpu       :2550 [interfaces.py:monitor():144] Failed to sample metric: Not Supported
2024-03-13 00:05:54,542 DEBUG   HandlerThread:2550 [handler.py:handle_request():146] handle_request: status_report
2024-03-13 00:05:54,848 ERROR   gpu       :2550 [interfaces.py:monitor():144] Failed to sample metric: Not Supported
2024-03-13 00:05:54,848 ERROR   gpu       :2550 [interfaces.py:monitor():144] Failed to sample metric: Not Supported
2024-03-13 00:05:56,849 ERROR   gpu       :2550 [interfaces.py:monitor():144] Failed to sample metric: Not Supported
2024-03-13 00:05:56,849 ERROR   gpu       :2550 [interfaces.py:monitor():144] Failed to sample metric: Not Supported
2024-03-13 00:05:58,850 ERROR   gpu       :2550 [interfaces.py:monitor():144] Failed to sample metric: Not Supported
2024-03-13 00:05:58,850 ERROR   gpu       :2550 [interfaces.py:monitor():144] Failed to sample metric: Not Supported
2024-03-13 00:05:59,543 DEBUG   HandlerThread:2550 [handler.py:handle_request():146] handle_request: status_report
2024-03-13 00:06:00,852 ERROR   gpu       :2550 [interfaces.py:monitor():144] Failed to sample metric: Not Supported
2024-03-13 00:06:00,852 ERROR   gpu       :2550 [interfaces.py:monitor():144] Failed to sample metric: Not Supported
2024-03-13 00:06:02,853 ERROR   gpu       :2550 [interfaces.py:monitor():144] Failed to sample metric: Not Supported
2024-03-13 00:06:02,853 ERROR   gpu       :2550 [interfaces.py:monitor():144] Failed to sample metric: Not Supported
2024-03-13 00:06:03,172 DEBUG   HandlerThread:2550 [handler.py:handle_request():146] handle_request: stop_status
2024-03-13 00:06:03,172 DEBUG   HandlerThread:2550 [handler.py:handle_request():146] handle_request: internal_messages
2024-03-13 00:06:03,172 DEBUG   SenderThread:2550 [sender.py:send_request():407] send_request: stop_status
2024-03-13 00:06:04,854 ERROR   gpu       :2550 [interfaces.py:monitor():144] Failed to sample metric: Not Supported
2024-03-13 00:06:04,854 ERROR   gpu       :2550 [interfaces.py:monitor():144] Failed to sample metric: Not Supported
2024-03-13 00:06:05,376 DEBUG   HandlerThread:2550 [handler.py:handle_request():146] handle_request: status_report
2024-03-13 00:06:06,854 ERROR   gpu       :2550 [interfaces.py:monitor():144] Failed to sample metric: Not Supported
2024-03-13 00:06:06,854 ERROR   gpu       :2550 [interfaces.py:monitor():144] Failed to sample metric: Not Supported
2024-03-13 00:06:08,580 INFO    Thread-12 :2550 [dir_watcher.py:_on_file_created():271] file/dir created: /home/huseyin/fungtion/dannpy_yeniden/DANN_py3/wandb/run-20240313_000543-tirrr1qg/files/output.log
2024-03-13 00:06:08,855 ERROR   gpu       :2550 [interfaces.py:monitor():144] Failed to sample metric: Not Supported
2024-03-13 00:06:08,855 ERROR   gpu       :2550 [interfaces.py:monitor():144] Failed to sample metric: Not Supported
2024-03-13 00:06:10,581 INFO    Thread-12 :2550 [dir_watcher.py:_on_file_modified():288] file/dir modified: /home/huseyin/fungtion/dannpy_yeniden/DANN_py3/wandb/run-20240313_000543-tirrr1qg/files/output.log
2024-03-13 00:06:10,856 ERROR   gpu       :2550 [interfaces.py:monitor():144] Failed to sample metric: Not Supported
2024-03-13 00:06:10,856 ERROR   gpu       :2550 [interfaces.py:monitor():144] Failed to sample metric: Not Supported
2024-03-13 00:06:11,066 DEBUG   HandlerThread:2550 [handler.py:handle_request():146] handle_request: status_report
2024-03-13 00:06:12,856 ERROR   gpu       :2550 [interfaces.py:monitor():144] Failed to sample metric: Not Supported
2024-03-13 00:06:12,856 ERROR   gpu       :2550 [interfaces.py:monitor():144] Failed to sample metric: Not Supported
2024-03-13 00:06:14,582 INFO    Thread-12 :2550 [dir_watcher.py:_on_file_modified():288] file/dir modified: /home/huseyin/fungtion/dannpy_yeniden/DANN_py3/wandb/run-20240313_000543-tirrr1qg/files/output.log
2024-03-13 00:06:14,888 ERROR   gpu       :2550 [interfaces.py:aggregate():161] Failed to serialize metric: division by zero
2024-03-13 00:06:14,888 ERROR   gpu       :2550 [interfaces.py:monitor():144] Failed to sample metric: Not Supported
2024-03-13 00:06:14,888 ERROR   gpu       :2550 [interfaces.py:monitor():144] Failed to sample metric: Not Supported
2024-03-13 00:06:16,247 DEBUG   HandlerThread:2550 [handler.py:handle_request():146] handle_request: status_report
2024-03-13 00:06:16,258 DEBUG   HandlerThread:2550 [handler.py:handle_request():146] handle_request: partial_history
2024-03-13 00:06:16,583 INFO    Thread-12 :2550 [dir_watcher.py:_on_file_modified():288] file/dir modified: /home/huseyin/fungtion/dannpy_yeniden/DANN_py3/wandb/run-20240313_000543-tirrr1qg/files/config.yaml
2024-03-13 00:06:16,889 ERROR   gpu       :2550 [interfaces.py:monitor():144] Failed to sample metric: Not Supported
2024-03-13 00:06:16,889 ERROR   gpu       :2550 [interfaces.py:monitor():144] Failed to sample metric: Not Supported
2024-03-13 00:06:18,400 DEBUG   HandlerThread:2550 [handler.py:handle_request():146] handle_request: stop_status
2024-03-13 00:06:18,401 DEBUG   HandlerThread:2550 [handler.py:handle_request():146] handle_request: internal_messages
2024-03-13 00:06:18,401 DEBUG   SenderThread:2550 [sender.py:send_request():407] send_request: stop_status
2024-03-13 00:06:18,584 INFO    Thread-12 :2550 [dir_watcher.py:_on_file_modified():288] file/dir modified: /home/huseyin/fungtion/dannpy_yeniden/DANN_py3/wandb/run-20240313_000543-tirrr1qg/files/output.log
2024-03-13 00:06:18,889 ERROR   gpu       :2550 [interfaces.py:monitor():144] Failed to sample metric: Not Supported
2024-03-13 00:06:18,890 ERROR   gpu       :2550 [interfaces.py:monitor():144] Failed to sample metric: Not Supported
2024-03-13 00:06:20,890 ERROR   gpu       :2550 [interfaces.py:monitor():144] Failed to sample metric: Not Supported
2024-03-13 00:06:20,890 ERROR   gpu       :2550 [interfaces.py:monitor():144] Failed to sample metric: Not Supported
2024-03-13 00:06:21,681 DEBUG   HandlerThread:2550 [handler.py:handle_request():146] handle_request: status_report
2024-03-13 00:06:22,891 ERROR   gpu       :2550 [interfaces.py:monitor():144] Failed to sample metric: Not Supported
2024-03-13 00:06:22,891 ERROR   gpu       :2550 [interfaces.py:monitor():144] Failed to sample metric: Not Supported
2024-03-13 00:06:24,891 ERROR   gpu       :2550 [interfaces.py:monitor():144] Failed to sample metric: Not Supported
2024-03-13 00:06:24,892 ERROR   gpu       :2550 [interfaces.py:monitor():144] Failed to sample metric: Not Supported
2024-03-13 00:06:26,682 DEBUG   HandlerThread:2550 [handler.py:handle_request():146] handle_request: status_report
2024-03-13 00:06:26,892 ERROR   gpu       :2550 [interfaces.py:monitor():144] Failed to sample metric: Not Supported
2024-03-13 00:06:26,892 ERROR   gpu       :2550 [interfaces.py:monitor():144] Failed to sample metric: Not Supported
2024-03-13 00:06:28,893 ERROR   gpu       :2550 [interfaces.py:monitor():144] Failed to sample metric: Not Supported
2024-03-13 00:06:28,893 ERROR   gpu       :2550 [interfaces.py:monitor():144] Failed to sample metric: Not Supported
2024-03-13 00:06:30,893 ERROR   gpu       :2550 [interfaces.py:monitor():144] Failed to sample metric: Not Supported
2024-03-13 00:06:30,894 ERROR   gpu       :2550 [interfaces.py:monitor():144] Failed to sample metric: Not Supported
2024-03-13 00:06:32,588 INFO    Thread-12 :2550 [dir_watcher.py:_on_file_modified():288] file/dir modified: /home/huseyin/fungtion/dannpy_yeniden/DANN_py3/wandb/run-20240313_000543-tirrr1qg/files/output.log
2024-03-13 00:06:32,670 DEBUG   HandlerThread:2550 [handler.py:handle_request():146] handle_request: status_report
2024-03-13 00:06:32,894 ERROR   gpu       :2550 [interfaces.py:monitor():144] Failed to sample metric: Not Supported
2024-03-13 00:06:32,894 ERROR   gpu       :2550 [interfaces.py:monitor():144] Failed to sample metric: Not Supported
2024-03-13 00:06:33,397 DEBUG   HandlerThread:2550 [handler.py:handle_request():146] handle_request: stop_status
2024-03-13 00:06:33,398 DEBUG   HandlerThread:2550 [handler.py:handle_request():146] handle_request: internal_messages
2024-03-13 00:06:33,398 DEBUG   SenderThread:2550 [sender.py:send_request():407] send_request: stop_status
2024-03-13 00:06:34,895 ERROR   gpu       :2550 [interfaces.py:monitor():144] Failed to sample metric: Not Supported
2024-03-13 00:06:34,895 ERROR   gpu       :2550 [interfaces.py:monitor():144] Failed to sample metric: Not Supported
2024-03-13 00:06:36,589 INFO    Thread-12 :2550 [dir_watcher.py:_on_file_modified():288] file/dir modified: /home/huseyin/fungtion/dannpy_yeniden/DANN_py3/wandb/run-20240313_000543-tirrr1qg/files/output.log
2024-03-13 00:06:36,897 ERROR   gpu       :2550 [interfaces.py:monitor():144] Failed to sample metric: Not Supported
2024-03-13 00:06:36,897 ERROR   gpu       :2550 [interfaces.py:monitor():144] Failed to sample metric: Not Supported
2024-03-13 00:06:37,878 DEBUG   HandlerThread:2550 [handler.py:handle_request():146] handle_request: status_report
2024-03-13 00:06:38,897 ERROR   gpu       :2550 [interfaces.py:monitor():144] Failed to sample metric: Not Supported
2024-03-13 00:06:38,897 ERROR   gpu       :2550 [interfaces.py:monitor():144] Failed to sample metric: Not Supported
2024-03-13 00:06:39,685 DEBUG   HandlerThread:2550 [handler.py:handle_request():146] handle_request: partial_history
2024-03-13 00:06:39,687 DEBUG   SenderThread:2550 [sender.py:send():380] send: history
2024-03-13 00:06:39,688 DEBUG   SenderThread:2550 [sender.py:send_request():407] send_request: summary_record
2024-03-13 00:06:39,689 INFO    SenderThread:2550 [sender.py:_save_file():1378] saving file wandb-summary.json with policy end
2024-03-13 00:06:39,853 ERROR   FileStreamThread:2550 [file_stream.py:_handle_response():504] dropped chunk 404 Client Error: Not Found for url: https://api.wandb.ai/files/hkaraca/dimchange2/tirrr1qg/file_stream
NoneType: None
2024-03-13 00:06:40,590 INFO    Thread-12 :2550 [dir_watcher.py:_on_file_modified():288] file/dir modified: /home/huseyin/fungtion/dannpy_yeniden/DANN_py3/wandb/run-20240313_000543-tirrr1qg/files/output.log
2024-03-13 00:06:40,591 INFO    Thread-12 :2550 [dir_watcher.py:_on_file_created():271] file/dir created: /home/huseyin/fungtion/dannpy_yeniden/DANN_py3/wandb/run-20240313_000543-tirrr1qg/files/wandb-summary.json
2024-03-13 00:06:40,898 ERROR   gpu       :2550 [interfaces.py:monitor():144] Failed to sample metric: Not Supported
2024-03-13 00:06:40,898 ERROR   gpu       :2550 [interfaces.py:monitor():144] Failed to sample metric: Not Supported
2024-03-13 00:06:42,234 ERROR   FileStreamThread:2550 [file_stream.py:_handle_response():504] dropped chunk 404 Client Error: Not Found for url: https://api.wandb.ai/files/hkaraca/dimchange2/tirrr1qg/file_stream
NoneType: None
2024-03-13 00:06:42,899 ERROR   gpu       :2550 [interfaces.py:monitor():144] Failed to sample metric: Not Supported
2024-03-13 00:06:42,899 ERROR   gpu       :2550 [interfaces.py:monitor():144] Failed to sample metric: Not Supported
2024-03-13 00:06:43,690 DEBUG   HandlerThread:2550 [handler.py:handle_request():146] handle_request: status_report
2024-03-13 00:06:44,840 DEBUG   SystemMonitor:2550 [system_monitor.py:_start():172] Starting system metrics aggregation loop
2024-03-13 00:06:44,841 DEBUG   SenderThread:2550 [sender.py:send():380] send: stats
2024-03-13 00:06:44,926 ERROR   gpu       :2550 [interfaces.py:aggregate():161] Failed to serialize metric: division by zero
2024-03-13 00:06:44,926 ERROR   gpu       :2550 [interfaces.py:monitor():144] Failed to sample metric: Not Supported
2024-03-13 00:06:44,928 ERROR   gpu       :2550 [interfaces.py:monitor():144] Failed to sample metric: Not Supported
2024-03-13 00:06:46,929 ERROR   gpu       :2550 [interfaces.py:monitor():144] Failed to sample metric: Not Supported
2024-03-13 00:06:46,929 ERROR   gpu       :2550 [interfaces.py:monitor():144] Failed to sample metric: Not Supported
2024-03-13 00:06:48,399 DEBUG   HandlerThread:2550 [handler.py:handle_request():146] handle_request: stop_status
2024-03-13 00:06:48,399 DEBUG   SenderThread:2550 [sender.py:send_request():407] send_request: stop_status
2024-03-13 00:06:48,400 DEBUG   HandlerThread:2550 [handler.py:handle_request():146] handle_request: internal_messages
2024-03-13 00:06:48,930 ERROR   gpu       :2550 [interfaces.py:monitor():144] Failed to sample metric: Not Supported
2024-03-13 00:06:48,930 ERROR   gpu       :2550 [interfaces.py:monitor():144] Failed to sample metric: Not Supported
2024-03-13 00:06:49,636 DEBUG   HandlerThread:2550 [handler.py:handle_request():146] handle_request: status_report
2024-03-13 00:06:50,931 ERROR   gpu       :2550 [interfaces.py:monitor():144] Failed to sample metric: Not Supported
2024-03-13 00:06:50,931 ERROR   gpu       :2550 [interfaces.py:monitor():144] Failed to sample metric: Not Supported
2024-03-13 00:06:52,932 ERROR   gpu       :2550 [interfaces.py:monitor():144] Failed to sample metric: Not Supported
2024-03-13 00:06:52,932 ERROR   gpu       :2550 [interfaces.py:monitor():144] Failed to sample metric: Not Supported
2024-03-13 00:06:54,636 DEBUG   HandlerThread:2550 [handler.py:handle_request():146] handle_request: status_report
2024-03-13 00:06:54,932 ERROR   gpu       :2550 [interfaces.py:monitor():144] Failed to sample metric: Not Supported
2024-03-13 00:06:54,932 ERROR   gpu       :2550 [interfaces.py:monitor():144] Failed to sample metric: Not Supported
2024-03-13 00:06:55,010 ERROR   FileStreamThread:2550 [file_stream.py:_handle_response():504] dropped chunk 404 Client Error: Not Found for url: https://api.wandb.ai/files/hkaraca/dimchange2/tirrr1qg/file_stream
NoneType: None
2024-03-13 00:06:56,933 ERROR   gpu       :2550 [interfaces.py:monitor():144] Failed to sample metric: Not Supported
2024-03-13 00:06:56,933 ERROR   gpu       :2550 [interfaces.py:monitor():144] Failed to sample metric: Not Supported
2024-03-13 00:06:58,597 INFO    Thread-12 :2550 [dir_watcher.py:_on_file_modified():288] file/dir modified: /home/huseyin/fungtion/dannpy_yeniden/DANN_py3/wandb/run-20240313_000543-tirrr1qg/files/output.log
2024-03-13 00:06:58,934 ERROR   gpu       :2550 [interfaces.py:monitor():144] Failed to sample metric: Not Supported
2024-03-13 00:06:58,934 ERROR   gpu       :2550 [interfaces.py:monitor():144] Failed to sample metric: Not Supported
2024-03-13 00:06:59,654 DEBUG   HandlerThread:2550 [handler.py:handle_request():146] handle_request: status_report
2024-03-13 00:07:00,934 ERROR   gpu       :2550 [interfaces.py:monitor():144] Failed to sample metric: Not Supported
2024-03-13 00:07:00,934 ERROR   gpu       :2550 [interfaces.py:monitor():144] Failed to sample metric: Not Supported
2024-03-13 00:07:02,598 INFO    Thread-12 :2550 [dir_watcher.py:_on_file_modified():288] file/dir modified: /home/huseyin/fungtion/dannpy_yeniden/DANN_py3/wandb/run-20240313_000543-tirrr1qg/files/output.log
2024-03-13 00:07:02,935 ERROR   gpu       :2550 [interfaces.py:monitor():144] Failed to sample metric: Not Supported
2024-03-13 00:07:02,935 ERROR   gpu       :2550 [interfaces.py:monitor():144] Failed to sample metric: Not Supported
2024-03-13 00:07:03,398 DEBUG   HandlerThread:2550 [handler.py:handle_request():146] handle_request: stop_status
2024-03-13 00:07:03,398 DEBUG   SenderThread:2550 [sender.py:send_request():407] send_request: stop_status
2024-03-13 00:07:03,400 DEBUG   HandlerThread:2550 [handler.py:handle_request():146] handle_request: internal_messages
2024-03-13 00:07:04,656 DEBUG   HandlerThread:2550 [handler.py:handle_request():146] handle_request: status_report
2024-03-13 00:07:04,697 DEBUG   HandlerThread:2550 [handler.py:handle_request():146] handle_request: partial_history
2024-03-13 00:07:04,699 DEBUG   SenderThread:2550 [sender.py:send():380] send: history
2024-03-13 00:07:04,699 DEBUG   SenderThread:2550 [sender.py:send_request():407] send_request: summary_record
2024-03-13 00:07:04,699 INFO    SenderThread:2550 [sender.py:_save_file():1378] saving file wandb-summary.json with policy end
2024-03-13 00:07:04,936 ERROR   gpu       :2550 [interfaces.py:monitor():144] Failed to sample metric: Not Supported
2024-03-13 00:07:04,936 ERROR   gpu       :2550 [interfaces.py:monitor():144] Failed to sample metric: Not Supported
2024-03-13 00:07:05,599 INFO    Thread-12 :2550 [dir_watcher.py:_on_file_modified():288] file/dir modified: /home/huseyin/fungtion/dannpy_yeniden/DANN_py3/wandb/run-20240313_000543-tirrr1qg/files/wandb-summary.json
2024-03-13 00:07:06,263 ERROR   FileStreamThread:2550 [file_stream.py:_handle_response():504] dropped chunk 404 Client Error: Not Found for url: https://api.wandb.ai/files/hkaraca/dimchange2/tirrr1qg/file_stream
NoneType: None
2024-03-13 00:07:06,599 INFO    Thread-12 :2550 [dir_watcher.py:_on_file_modified():288] file/dir modified: /home/huseyin/fungtion/dannpy_yeniden/DANN_py3/wandb/run-20240313_000543-tirrr1qg/files/output.log
2024-03-13 00:07:06,936 ERROR   gpu       :2550 [interfaces.py:monitor():144] Failed to sample metric: Not Supported
2024-03-13 00:07:06,936 ERROR   gpu       :2550 [interfaces.py:monitor():144] Failed to sample metric: Not Supported
2024-03-13 00:07:08,937 ERROR   gpu       :2550 [interfaces.py:monitor():144] Failed to sample metric: Not Supported
2024-03-13 00:07:08,937 ERROR   gpu       :2550 [interfaces.py:monitor():144] Failed to sample metric: Not Supported
2024-03-13 00:07:09,700 DEBUG   HandlerThread:2550 [handler.py:handle_request():146] handle_request: status_report
2024-03-13 00:07:10,938 ERROR   gpu       :2550 [interfaces.py:monitor():144] Failed to sample metric: Not Supported
2024-03-13 00:07:10,938 ERROR   gpu       :2550 [interfaces.py:monitor():144] Failed to sample metric: Not Supported
2024-03-13 00:07:12,940 ERROR   gpu       :2550 [interfaces.py:monitor():144] Failed to sample metric: Not Supported
2024-03-13 00:07:12,940 ERROR   gpu       :2550 [interfaces.py:monitor():144] Failed to sample metric: Not Supported
2024-03-13 00:07:14,701 DEBUG   HandlerThread:2550 [handler.py:handle_request():146] handle_request: status_report
2024-03-13 00:07:14,842 DEBUG   SenderThread:2550 [sender.py:send():380] send: stats
2024-03-13 00:07:14,967 ERROR   gpu       :2550 [interfaces.py:aggregate():161] Failed to serialize metric: division by zero
2024-03-13 00:07:14,967 ERROR   gpu       :2550 [interfaces.py:monitor():144] Failed to sample metric: Not Supported
2024-03-13 00:07:14,967 ERROR   gpu       :2550 [interfaces.py:monitor():144] Failed to sample metric: Not Supported
2024-03-13 00:07:16,148 DEBUG   SenderThread:2550 [sender.py:send():380] send: exit
2024-03-13 00:07:16,148 INFO    SenderThread:2550 [sender.py:send_exit():585] handling exit code: 255
2024-03-13 00:07:16,148 INFO    SenderThread:2550 [sender.py:send_exit():587] handling runtime: 91
2024-03-13 00:07:16,150 INFO    SenderThread:2550 [sender.py:_save_file():1378] saving file wandb-summary.json with policy end
2024-03-13 00:07:16,151 INFO    SenderThread:2550 [sender.py:send_exit():593] send defer
2024-03-13 00:07:16,151 DEBUG   HandlerThread:2550 [handler.py:handle_request():146] handle_request: defer
2024-03-13 00:07:16,151 INFO    HandlerThread:2550 [handler.py:handle_request_defer():172] handle defer: 0
2024-03-13 00:07:16,151 DEBUG   SenderThread:2550 [sender.py:send_request():407] send_request: defer
2024-03-13 00:07:16,151 INFO    SenderThread:2550 [sender.py:send_request_defer():609] handle sender defer: 0
2024-03-13 00:07:16,151 INFO    SenderThread:2550 [sender.py:transition_state():613] send defer: 1
2024-03-13 00:07:16,151 DEBUG   HandlerThread:2550 [handler.py:handle_request():146] handle_request: defer
2024-03-13 00:07:16,151 INFO    HandlerThread:2550 [handler.py:handle_request_defer():172] handle defer: 1
2024-03-13 00:07:16,152 DEBUG   SenderThread:2550 [sender.py:send_request():407] send_request: defer
2024-03-13 00:07:16,152 INFO    SenderThread:2550 [sender.py:send_request_defer():609] handle sender defer: 1
2024-03-13 00:07:16,152 INFO    SenderThread:2550 [sender.py:transition_state():613] send defer: 2
2024-03-13 00:07:16,152 DEBUG   HandlerThread:2550 [handler.py:handle_request():146] handle_request: defer
2024-03-13 00:07:16,152 INFO    HandlerThread:2550 [handler.py:handle_request_defer():172] handle defer: 2
2024-03-13 00:07:16,152 INFO    HandlerThread:2550 [system_monitor.py:finish():203] Stopping system monitor
2024-03-13 00:07:16,152 DEBUG   SystemMonitor:2550 [system_monitor.py:_start():179] Finished system metrics aggregation loop
2024-03-13 00:07:16,152 DEBUG   SystemMonitor:2550 [system_monitor.py:_start():183] Publishing last batch of metrics
2024-03-13 00:07:16,153 INFO    HandlerThread:2550 [interfaces.py:finish():202] Joined cpu monitor
2024-03-13 00:07:16,153 INFO    HandlerThread:2550 [interfaces.py:finish():202] Joined disk monitor
2024-03-13 00:07:16,180 ERROR   gpu       :2550 [interfaces.py:aggregate():161] Failed to serialize metric: division by zero
2024-03-13 00:07:16,181 INFO    HandlerThread:2550 [interfaces.py:finish():202] Joined gpu monitor
2024-03-13 00:07:16,181 INFO    HandlerThread:2550 [interfaces.py:finish():202] Joined memory monitor
2024-03-13 00:07:16,181 INFO    HandlerThread:2550 [interfaces.py:finish():202] Joined network monitor
2024-03-13 00:07:16,182 DEBUG   SenderThread:2550 [sender.py:send_request():407] send_request: defer
2024-03-13 00:07:16,182 INFO    SenderThread:2550 [sender.py:send_request_defer():609] handle sender defer: 2
2024-03-13 00:07:16,182 INFO    SenderThread:2550 [sender.py:transition_state():613] send defer: 3
2024-03-13 00:07:16,182 DEBUG   SenderThread:2550 [sender.py:send():380] send: stats
2024-03-13 00:07:16,182 DEBUG   HandlerThread:2550 [handler.py:handle_request():146] handle_request: defer
2024-03-13 00:07:16,183 INFO    HandlerThread:2550 [handler.py:handle_request_defer():172] handle defer: 3
2024-03-13 00:07:16,184 DEBUG   SenderThread:2550 [sender.py:send():380] send: history
2024-03-13 00:07:16,184 DEBUG   SenderThread:2550 [sender.py:send_request():407] send_request: summary_record
2024-03-13 00:07:16,184 INFO    SenderThread:2550 [sender.py:_save_file():1378] saving file wandb-summary.json with policy end
2024-03-13 00:07:16,184 DEBUG   SenderThread:2550 [sender.py:send_request():407] send_request: defer
2024-03-13 00:07:16,184 INFO    SenderThread:2550 [sender.py:send_request_defer():609] handle sender defer: 3
2024-03-13 00:07:16,184 INFO    SenderThread:2550 [sender.py:transition_state():613] send defer: 4
2024-03-13 00:07:16,184 DEBUG   HandlerThread:2550 [handler.py:handle_request():146] handle_request: defer
2024-03-13 00:07:16,184 INFO    HandlerThread:2550 [handler.py:handle_request_defer():172] handle defer: 4
2024-03-13 00:07:16,185 DEBUG   SenderThread:2550 [sender.py:send_request():407] send_request: defer
2024-03-13 00:07:16,185 INFO    SenderThread:2550 [sender.py:send_request_defer():609] handle sender defer: 4
2024-03-13 00:07:16,185 INFO    SenderThread:2550 [sender.py:transition_state():613] send defer: 5
2024-03-13 00:07:16,185 DEBUG   HandlerThread:2550 [handler.py:handle_request():146] handle_request: defer
2024-03-13 00:07:16,185 INFO    HandlerThread:2550 [handler.py:handle_request_defer():172] handle defer: 5
2024-03-13 00:07:16,186 DEBUG   SenderThread:2550 [sender.py:send():380] send: summary
2024-03-13 00:07:16,186 INFO    SenderThread:2550 [sender.py:_save_file():1378] saving file wandb-summary.json with policy end
2024-03-13 00:07:16,186 DEBUG   SenderThread:2550 [sender.py:send_request():407] send_request: defer
2024-03-13 00:07:16,186 INFO    SenderThread:2550 [sender.py:send_request_defer():609] handle sender defer: 5
2024-03-13 00:07:16,186 INFO    SenderThread:2550 [sender.py:transition_state():613] send defer: 6
2024-03-13 00:07:16,186 DEBUG   HandlerThread:2550 [handler.py:handle_request():146] handle_request: defer
2024-03-13 00:07:16,187 INFO    HandlerThread:2550 [handler.py:handle_request_defer():172] handle defer: 6
2024-03-13 00:07:16,187 DEBUG   SenderThread:2550 [sender.py:send_request():407] send_request: defer
2024-03-13 00:07:16,187 INFO    SenderThread:2550 [sender.py:send_request_defer():609] handle sender defer: 6
2024-03-13 00:07:16,187 INFO    SenderThread:2550 [sender.py:transition_state():613] send defer: 7
2024-03-13 00:07:16,187 DEBUG   HandlerThread:2550 [handler.py:handle_request():146] handle_request: status_report
2024-03-13 00:07:16,187 DEBUG   HandlerThread:2550 [handler.py:handle_request():146] handle_request: defer
2024-03-13 00:07:16,187 INFO    HandlerThread:2550 [handler.py:handle_request_defer():172] handle defer: 7
2024-03-13 00:07:16,188 DEBUG   SenderThread:2550 [sender.py:send_request():407] send_request: defer
2024-03-13 00:07:16,188 INFO    SenderThread:2550 [sender.py:send_request_defer():609] handle sender defer: 7
2024-03-13 00:07:16,315 ERROR   FileStreamThread:2550 [file_stream.py:_handle_response():504] dropped chunk 404 Client Error: Not Found for url: https://api.wandb.ai/files/hkaraca/dimchange2/tirrr1qg/file_stream
NoneType: None
2024-03-13 00:07:16,603 INFO    Thread-12 :2550 [dir_watcher.py:_on_file_modified():288] file/dir modified: /home/huseyin/fungtion/dannpy_yeniden/DANN_py3/wandb/run-20240313_000543-tirrr1qg/files/wandb-summary.json
2024-03-13 00:07:17,149 DEBUG   HandlerThread:2550 [handler.py:handle_request():146] handle_request: poll_exit
2024-03-13 00:07:18,162 INFO    SenderThread:2550 [sender.py:transition_state():613] send defer: 8
2024-03-13 00:07:18,163 DEBUG   SenderThread:2550 [sender.py:send_request():407] send_request: poll_exit
2024-03-13 00:07:18,163 DEBUG   HandlerThread:2550 [handler.py:handle_request():146] handle_request: defer
2024-03-13 00:07:18,163 INFO    HandlerThread:2550 [handler.py:handle_request_defer():172] handle defer: 8
2024-03-13 00:07:18,163 DEBUG   SenderThread:2550 [sender.py:send_request():407] send_request: defer
2024-03-13 00:07:18,163 INFO    SenderThread:2550 [sender.py:send_request_defer():609] handle sender defer: 8
2024-03-13 00:07:18,164 INFO    SenderThread:2550 [job_builder.py:build():281] Attempting to build job artifact
2024-03-13 00:07:18,164 INFO    SenderThread:2550 [job_builder.py:_get_source_type():393] is repo sourced job
2024-03-13 00:07:18,166 INFO    SenderThread:2550 [job_builder.py:build():369] adding wandb-job metadata file
2024-03-13 00:07:18,170 INFO    SenderThread:2550 [sender.py:transition_state():613] send defer: 9
2024-03-13 00:07:18,170 DEBUG   HandlerThread:2550 [handler.py:handle_request():146] handle_request: defer
2024-03-13 00:07:18,170 INFO    HandlerThread:2550 [handler.py:handle_request_defer():172] handle defer: 9
2024-03-13 00:07:18,170 DEBUG   SenderThread:2550 [sender.py:send():380] send: artifact
2024-03-13 00:07:18,604 INFO    Thread-12 :2550 [dir_watcher.py:_on_file_modified():288] file/dir modified: /home/huseyin/fungtion/dannpy_yeniden/DANN_py3/wandb/run-20240313_000543-tirrr1qg/files/output.log
2024-03-13 00:07:18,631 ERROR   SenderThread:2550 [internal_api.py:execute():369] 404 response executing GraphQL.
2024-03-13 00:07:18,632 ERROR   SenderThread:2550 [internal_api.py:execute():370] {"errors":[{"message":"failed to find run dimchange2/tirrr1qg","path":["createArtifactManifest"]}],"data":{"createArtifactManifest":null}}
2024-03-13 00:07:18,632 ERROR   SenderThread:2550 [sender.py:send_artifact():1458] send_artifact: failed for artifact "job/job-https___github.com_huseyin-karaca_DANN_py3.git_main.py": It appears that you do not have permission to access the requested resource. Please reach out to the project owner to grant you access. If you have the correct permissions, verify that there are no issues with your networking setup.(Error 404: Not Found)
2024-03-13 00:07:18,633 DEBUG   SenderThread:2550 [sender.py:send_request():407] send_request: defer
2024-03-13 00:07:18,633 INFO    SenderThread:2550 [sender.py:send_request_defer():609] handle sender defer: 9
2024-03-13 00:07:18,633 INFO    SenderThread:2550 [dir_watcher.py:finish():358] shutting down directory watcher
2024-03-13 00:07:19,607 INFO    SenderThread:2550 [dir_watcher.py:finish():388] scan: /home/huseyin/fungtion/dannpy_yeniden/DANN_py3/wandb/run-20240313_000543-tirrr1qg/files
2024-03-13 00:07:19,607 INFO    SenderThread:2550 [dir_watcher.py:finish():402] scan save: /home/huseyin/fungtion/dannpy_yeniden/DANN_py3/wandb/run-20240313_000543-tirrr1qg/files/output.log output.log
2024-03-13 00:07:19,608 INFO    SenderThread:2550 [dir_watcher.py:finish():402] scan save: /home/huseyin/fungtion/dannpy_yeniden/DANN_py3/wandb/run-20240313_000543-tirrr1qg/files/wandb-metadata.json wandb-metadata.json
2024-03-13 00:07:19,608 INFO    SenderThread:2550 [dir_watcher.py:finish():402] scan save: /home/huseyin/fungtion/dannpy_yeniden/DANN_py3/wandb/run-20240313_000543-tirrr1qg/files/config.yaml config.yaml
2024-03-13 00:07:19,609 INFO    SenderThread:2550 [dir_watcher.py:finish():402] scan save: /home/huseyin/fungtion/dannpy_yeniden/DANN_py3/wandb/run-20240313_000543-tirrr1qg/files/diff.patch diff.patch
2024-03-13 00:07:19,609 INFO    SenderThread:2550 [dir_watcher.py:finish():402] scan save: /home/huseyin/fungtion/dannpy_yeniden/DANN_py3/wandb/run-20240313_000543-tirrr1qg/files/wandb-summary.json wandb-summary.json
2024-03-13 00:07:19,610 INFO    SenderThread:2550 [dir_watcher.py:finish():402] scan save: /home/huseyin/fungtion/dannpy_yeniden/DANN_py3/wandb/run-20240313_000543-tirrr1qg/files/conda-environment.yaml conda-environment.yaml
2024-03-13 00:07:19,618 INFO    SenderThread:2550 [dir_watcher.py:finish():402] scan save: /home/huseyin/fungtion/dannpy_yeniden/DANN_py3/wandb/run-20240313_000543-tirrr1qg/files/requirements.txt requirements.txt
2024-03-13 00:07:19,630 INFO    SenderThread:2550 [dir_watcher.py:finish():402] scan save: /home/huseyin/fungtion/dannpy_yeniden/DANN_py3/wandb/run-20240313_000543-tirrr1qg/files/code/main.py code/main.py
2024-03-13 00:07:19,630 INFO    SenderThread:2550 [sender.py:transition_state():613] send defer: 10
2024-03-13 00:07:19,630 DEBUG   HandlerThread:2550 [handler.py:handle_request():146] handle_request: defer
2024-03-13 00:07:19,630 INFO    HandlerThread:2550 [handler.py:handle_request_defer():172] handle defer: 10
2024-03-13 00:07:19,631 DEBUG   SenderThread:2550 [sender.py:send_request():407] send_request: defer
2024-03-13 00:07:19,631 INFO    SenderThread:2550 [sender.py:send_request_defer():609] handle sender defer: 10
2024-03-13 00:07:19,631 INFO    SenderThread:2550 [file_pusher.py:finish():175] shutting down file pusher
2024-03-13 00:07:19,792 ERROR   wandb-upload_1:2550 [internal_api.py:execute():369] 404 response executing GraphQL.
2024-03-13 00:07:19,793 ERROR   wandb-upload_1:2550 [internal_api.py:execute():370] {"errors":[{"message":"run dimchange2/tirrr1qg not found during createRunFiles","path":["createRunFiles"]}],"data":{"createRunFiles":null}}
2024-03-13 00:07:19,795 ERROR   wandb-upload_0:2550 [internal_api.py:execute():369] 404 response executing GraphQL.
2024-03-13 00:07:19,795 ERROR   wandb-upload_0:2550 [internal_api.py:execute():370] {"errors":[{"message":"run dimchange2/tirrr1qg not found during createRunFiles","path":["createRunFiles"]}],"data":{"createRunFiles":null}}
2024-03-13 00:07:19,796 ERROR   Thread-11 :2550 [step_upload.py:_handle_event():200] Failed to upload file: /home/huseyin/fungtion/dannpy_yeniden/DANN_py3/wandb/run-20240313_000543-tirrr1qg/files/wandb-summary.json
Traceback (most recent call last):
  File "/home/huseyin/.local/lib/python3.8/site-packages/wandb/sdk/lib/retry.py", line 131, in __call__
    result = self._call_fn(*args, **kwargs)
  File "/home/huseyin/.local/lib/python3.8/site-packages/wandb/sdk/internal/internal_api.py", line 366, in execute
    return self.client.execute(*args, **kwargs)  # type: ignore
  File "/home/huseyin/.local/lib/python3.8/site-packages/wandb/vendor/gql-0.2.0/wandb_gql/client.py", line 52, in execute
    result = self._get_result(document, *args, **kwargs)
  File "/home/huseyin/.local/lib/python3.8/site-packages/wandb/vendor/gql-0.2.0/wandb_gql/client.py", line 60, in _get_result
    return self.transport.execute(document, *args, **kwargs)
  File "/home/huseyin/.local/lib/python3.8/site-packages/wandb/sdk/lib/gql_request.py", line 59, in execute
    request.raise_for_status()
  File "/home/huseyin/.local/lib/python3.8/site-packages/requests/models.py", line 1021, in raise_for_status
    raise HTTPError(http_error_msg, response=self)
requests.exceptions.HTTPError: 404 Client Error: Not Found for url: https://api.wandb.ai/graphql

During handling of the above exception, another exception occurred:

Traceback (most recent call last):
  File "/home/huseyin/anaconda3/envs/dannpy5/lib/python3.8/concurrent/futures/thread.py", line 57, in run
    result = self.fn(*self.args, **self.kwargs)
  File "/home/huseyin/.local/lib/python3.8/site-packages/wandb/filesync/step_upload.py", line 288, in run_and_notify
    self._do_upload_sync(event)
  File "/home/huseyin/.local/lib/python3.8/site-packages/wandb/filesync/step_upload.py", line 330, in _do_upload_sync
    job.run()
  File "/home/huseyin/.local/lib/python3.8/site-packages/wandb/filesync/upload_job.py", line 57, in run
    self.push()
  File "/home/huseyin/.local/lib/python3.8/site-packages/wandb/filesync/upload_job.py", line 106, in push
    _, upload_headers, result = self._api.upload_urls(project, [self.save_name])
  File "/home/huseyin/.local/lib/python3.8/site-packages/wandb/apis/normalize.py", line 73, in wrapper
    raise err
  File "/home/huseyin/.local/lib/python3.8/site-packages/wandb/apis/normalize.py", line 41, in wrapper
    return func(*args, **kwargs)
  File "/home/huseyin/.local/lib/python3.8/site-packages/wandb/sdk/internal/internal_api.py", line 2175, in upload_urls
    query_result = self.gql(
  File "/home/huseyin/.local/lib/python3.8/site-packages/wandb/sdk/internal/internal_api.py", line 338, in gql
    ret = self._retry_gql(
  File "/home/huseyin/.local/lib/python3.8/site-packages/wandb/sdk/lib/retry.py", line 147, in __call__
    retry_timedelta_triggered = check_retry_fn(e)
  File "/home/huseyin/.local/lib/python3.8/site-packages/wandb/util.py", line 906, in no_retry_auth
    raise CommError(
wandb.errors.CommError: It appears that you do not have permission to access the requested resource. Please reach out to the project owner to grant you access. If you have the correct permissions, verify that there are no issues with your networking setup.(Error 404: Not Found)
2024-03-13 00:07:19,801 ERROR   wandb-upload_2:2550 [internal_api.py:execute():369] 404 response executing GraphQL.
2024-03-13 00:07:19,803 ERROR   wandb-upload_3:2550 [internal_api.py:execute():369] 404 response executing GraphQL.
2024-03-13 00:07:19,811 ERROR   Thread-11 :2550 [step_upload.py:_handle_event():200] Failed to upload file: /home/huseyin/fungtion/dannpy_yeniden/DANN_py3/wandb/run-20240313_000543-tirrr1qg/files/output.log
Traceback (most recent call last):
  File "/home/huseyin/.local/lib/python3.8/site-packages/wandb/sdk/lib/retry.py", line 131, in __call__
    result = self._call_fn(*args, **kwargs)
  File "/home/huseyin/.local/lib/python3.8/site-packages/wandb/sdk/internal/internal_api.py", line 366, in execute
    return self.client.execute(*args, **kwargs)  # type: ignore
  File "/home/huseyin/.local/lib/python3.8/site-packages/wandb/vendor/gql-0.2.0/wandb_gql/client.py", line 52, in execute
    result = self._get_result(document, *args, **kwargs)
  File "/home/huseyin/.local/lib/python3.8/site-packages/wandb/vendor/gql-0.2.0/wandb_gql/client.py", line 60, in _get_result
    return self.transport.execute(document, *args, **kwargs)
  File "/home/huseyin/.local/lib/python3.8/site-packages/wandb/sdk/lib/gql_request.py", line 59, in execute
    request.raise_for_status()
  File "/home/huseyin/.local/lib/python3.8/site-packages/requests/models.py", line 1021, in raise_for_status
    raise HTTPError(http_error_msg, response=self)
requests.exceptions.HTTPError: 404 Client Error: Not Found for url: https://api.wandb.ai/graphql

During handling of the above exception, another exception occurred:

Traceback (most recent call last):
  File "/home/huseyin/anaconda3/envs/dannpy5/lib/python3.8/concurrent/futures/thread.py", line 57, in run
    result = self.fn(*self.args, **self.kwargs)
  File "/home/huseyin/.local/lib/python3.8/site-packages/wandb/filesync/step_upload.py", line 288, in run_and_notify
    self._do_upload_sync(event)
  File "/home/huseyin/.local/lib/python3.8/site-packages/wandb/filesync/step_upload.py", line 330, in _do_upload_sync
    job.run()
  File "/home/huseyin/.local/lib/python3.8/site-packages/wandb/filesync/upload_job.py", line 57, in run
    self.push()
  File "/home/huseyin/.local/lib/python3.8/site-packages/wandb/filesync/upload_job.py", line 106, in push
    _, upload_headers, result = self._api.upload_urls(project, [self.save_name])
  File "/home/huseyin/.local/lib/python3.8/site-packages/wandb/apis/normalize.py", line 73, in wrapper
    raise err
  File "/home/huseyin/.local/lib/python3.8/site-packages/wandb/apis/normalize.py", line 41, in wrapper
    return func(*args, **kwargs)
  File "/home/huseyin/.local/lib/python3.8/site-packages/wandb/sdk/internal/internal_api.py", line 2175, in upload_urls
    query_result = self.gql(
  File "/home/huseyin/.local/lib/python3.8/site-packages/wandb/sdk/internal/internal_api.py", line 338, in gql
    ret = self._retry_gql(
  File "/home/huseyin/.local/lib/python3.8/site-packages/wandb/sdk/lib/retry.py", line 147, in __call__
    retry_timedelta_triggered = check_retry_fn(e)
  File "/home/huseyin/.local/lib/python3.8/site-packages/wandb/util.py", line 906, in no_retry_auth
    raise CommError(
wandb.errors.CommError: It appears that you do not have permission to access the requested resource. Please reach out to the project owner to grant you access. If you have the correct permissions, verify that there are no issues with your networking setup.(Error 404: Not Found)
2024-03-13 00:07:19,811 ERROR   wandb-upload_2:2550 [internal_api.py:execute():370] {"errors":[{"message":"run dimchange2/tirrr1qg not found during createRunFiles","path":["createRunFiles"]}],"data":{"createRunFiles":null}}
2024-03-13 00:07:19,812 ERROR   wandb-upload_3:2550 [internal_api.py:execute():370] {"errors":[{"message":"run dimchange2/tirrr1qg not found during createRunFiles","path":["createRunFiles"]}],"data":{"createRunFiles":null}}
2024-03-13 00:07:19,814 ERROR   Thread-11 :2550 [step_upload.py:_handle_event():200] Failed to upload file: /home/huseyin/fungtion/dannpy_yeniden/DANN_py3/wandb/run-20240313_000543-tirrr1qg/files/config.yaml
Traceback (most recent call last):
  File "/home/huseyin/.local/lib/python3.8/site-packages/wandb/sdk/lib/retry.py", line 131, in __call__
    result = self._call_fn(*args, **kwargs)
  File "/home/huseyin/.local/lib/python3.8/site-packages/wandb/sdk/internal/internal_api.py", line 366, in execute
    return self.client.execute(*args, **kwargs)  # type: ignore
  File "/home/huseyin/.local/lib/python3.8/site-packages/wandb/vendor/gql-0.2.0/wandb_gql/client.py", line 52, in execute
    result = self._get_result(document, *args, **kwargs)
  File "/home/huseyin/.local/lib/python3.8/site-packages/wandb/vendor/gql-0.2.0/wandb_gql/client.py", line 60, in _get_result
    return self.transport.execute(document, *args, **kwargs)
  File "/home/huseyin/.local/lib/python3.8/site-packages/wandb/sdk/lib/gql_request.py", line 59, in execute
    request.raise_for_status()
  File "/home/huseyin/.local/lib/python3.8/site-packages/requests/models.py", line 1021, in raise_for_status
    raise HTTPError(http_error_msg, response=self)
requests.exceptions.HTTPError: 404 Client Error: Not Found for url: https://api.wandb.ai/graphql

During handling of the above exception, another exception occurred:

Traceback (most recent call last):
  File "/home/huseyin/anaconda3/envs/dannpy5/lib/python3.8/concurrent/futures/thread.py", line 57, in run
    result = self.fn(*self.args, **self.kwargs)
  File "/home/huseyin/.local/lib/python3.8/site-packages/wandb/filesync/step_upload.py", line 288, in run_and_notify
    self._do_upload_sync(event)
  File "/home/huseyin/.local/lib/python3.8/site-packages/wandb/filesync/step_upload.py", line 330, in _do_upload_sync
    job.run()
  File "/home/huseyin/.local/lib/python3.8/site-packages/wandb/filesync/upload_job.py", line 57, in run
    self.push()
  File "/home/huseyin/.local/lib/python3.8/site-packages/wandb/filesync/upload_job.py", line 106, in push
    _, upload_headers, result = self._api.upload_urls(project, [self.save_name])
  File "/home/huseyin/.local/lib/python3.8/site-packages/wandb/apis/normalize.py", line 73, in wrapper
    raise err
  File "/home/huseyin/.local/lib/python3.8/site-packages/wandb/apis/normalize.py", line 41, in wrapper
    return func(*args, **kwargs)
  File "/home/huseyin/.local/lib/python3.8/site-packages/wandb/sdk/internal/internal_api.py", line 2175, in upload_urls
    query_result = self.gql(
  File "/home/huseyin/.local/lib/python3.8/site-packages/wandb/sdk/internal/internal_api.py", line 338, in gql
    ret = self._retry_gql(
  File "/home/huseyin/.local/lib/python3.8/site-packages/wandb/sdk/lib/retry.py", line 147, in __call__
    retry_timedelta_triggered = check_retry_fn(e)
  File "/home/huseyin/.local/lib/python3.8/site-packages/wandb/util.py", line 906, in no_retry_auth
    raise CommError(
wandb.errors.CommError: It appears that you do not have permission to access the requested resource. Please reach out to the project owner to grant you access. If you have the correct permissions, verify that there are no issues with your networking setup.(Error 404: Not Found)
2024-03-13 00:07:19,815 ERROR   Thread-11 :2550 [step_upload.py:_handle_event():200] Failed to upload file: /home/huseyin/fungtion/dannpy_yeniden/DANN_py3/wandb/run-20240313_000543-tirrr1qg/files/conda-environment.yaml
Traceback (most recent call last):
  File "/home/huseyin/.local/lib/python3.8/site-packages/wandb/sdk/lib/retry.py", line 131, in __call__
    result = self._call_fn(*args, **kwargs)
  File "/home/huseyin/.local/lib/python3.8/site-packages/wandb/sdk/internal/internal_api.py", line 366, in execute
    return self.client.execute(*args, **kwargs)  # type: ignore
  File "/home/huseyin/.local/lib/python3.8/site-packages/wandb/vendor/gql-0.2.0/wandb_gql/client.py", line 52, in execute
    result = self._get_result(document, *args, **kwargs)
  File "/home/huseyin/.local/lib/python3.8/site-packages/wandb/vendor/gql-0.2.0/wandb_gql/client.py", line 60, in _get_result
    return self.transport.execute(document, *args, **kwargs)
  File "/home/huseyin/.local/lib/python3.8/site-packages/wandb/sdk/lib/gql_request.py", line 59, in execute
    request.raise_for_status()
  File "/home/huseyin/.local/lib/python3.8/site-packages/requests/models.py", line 1021, in raise_for_status
    raise HTTPError(http_error_msg, response=self)
requests.exceptions.HTTPError: 404 Client Error: Not Found for url: https://api.wandb.ai/graphql

During handling of the above exception, another exception occurred:

Traceback (most recent call last):
  File "/home/huseyin/anaconda3/envs/dannpy5/lib/python3.8/concurrent/futures/thread.py", line 57, in run
    result = self.fn(*self.args, **self.kwargs)
  File "/home/huseyin/.local/lib/python3.8/site-packages/wandb/filesync/step_upload.py", line 288, in run_and_notify
    self._do_upload_sync(event)
  File "/home/huseyin/.local/lib/python3.8/site-packages/wandb/filesync/step_upload.py", line 330, in _do_upload_sync
    job.run()
  File "/home/huseyin/.local/lib/python3.8/site-packages/wandb/filesync/upload_job.py", line 57, in run
    self.push()
  File "/home/huseyin/.local/lib/python3.8/site-packages/wandb/filesync/upload_job.py", line 106, in push
    _, upload_headers, result = self._api.upload_urls(project, [self.save_name])
  File "/home/huseyin/.local/lib/python3.8/site-packages/wandb/apis/normalize.py", line 73, in wrapper
    raise err
  File "/home/huseyin/.local/lib/python3.8/site-packages/wandb/apis/normalize.py", line 41, in wrapper
    return func(*args, **kwargs)
  File "/home/huseyin/.local/lib/python3.8/site-packages/wandb/sdk/internal/internal_api.py", line 2175, in upload_urls
    query_result = self.gql(
  File "/home/huseyin/.local/lib/python3.8/site-packages/wandb/sdk/internal/internal_api.py", line 338, in gql
    ret = self._retry_gql(
  File "/home/huseyin/.local/lib/python3.8/site-packages/wandb/sdk/lib/retry.py", line 147, in __call__
    retry_timedelta_triggered = check_retry_fn(e)
  File "/home/huseyin/.local/lib/python3.8/site-packages/wandb/util.py", line 906, in no_retry_auth
    raise CommError(
wandb.errors.CommError: It appears that you do not have permission to access the requested resource. Please reach out to the project owner to grant you access. If you have the correct permissions, verify that there are no issues with your networking setup.(Error 404: Not Found)
2024-03-13 00:07:19,870 ERROR   wandb-upload_4:2550 [internal_api.py:execute():369] 404 response executing GraphQL.
2024-03-13 00:07:19,870 ERROR   wandb-upload_4:2550 [internal_api.py:execute():370] {"errors":[{"message":"run dimchange2/tirrr1qg not found during createRunFiles","path":["createRunFiles"]}],"data":{"createRunFiles":null}}
2024-03-13 00:07:19,871 ERROR   Thread-11 :2550 [step_upload.py:_handle_event():200] Failed to upload file: /home/huseyin/fungtion/dannpy_yeniden/DANN_py3/wandb/run-20240313_000543-tirrr1qg/files/requirements.txt
Traceback (most recent call last):
  File "/home/huseyin/.local/lib/python3.8/site-packages/wandb/sdk/lib/retry.py", line 131, in __call__
    result = self._call_fn(*args, **kwargs)
  File "/home/huseyin/.local/lib/python3.8/site-packages/wandb/sdk/internal/internal_api.py", line 366, in execute
    return self.client.execute(*args, **kwargs)  # type: ignore
  File "/home/huseyin/.local/lib/python3.8/site-packages/wandb/vendor/gql-0.2.0/wandb_gql/client.py", line 52, in execute
    result = self._get_result(document, *args, **kwargs)
  File "/home/huseyin/.local/lib/python3.8/site-packages/wandb/vendor/gql-0.2.0/wandb_gql/client.py", line 60, in _get_result
    return self.transport.execute(document, *args, **kwargs)
  File "/home/huseyin/.local/lib/python3.8/site-packages/wandb/sdk/lib/gql_request.py", line 59, in execute
    request.raise_for_status()
  File "/home/huseyin/.local/lib/python3.8/site-packages/requests/models.py", line 1021, in raise_for_status
    raise HTTPError(http_error_msg, response=self)
requests.exceptions.HTTPError: 404 Client Error: Not Found for url: https://api.wandb.ai/graphql

During handling of the above exception, another exception occurred:

Traceback (most recent call last):
  File "/home/huseyin/anaconda3/envs/dannpy5/lib/python3.8/concurrent/futures/thread.py", line 57, in run
    result = self.fn(*self.args, **self.kwargs)
  File "/home/huseyin/.local/lib/python3.8/site-packages/wandb/filesync/step_upload.py", line 288, in run_and_notify
    self._do_upload_sync(event)
  File "/home/huseyin/.local/lib/python3.8/site-packages/wandb/filesync/step_upload.py", line 330, in _do_upload_sync
    job.run()
  File "/home/huseyin/.local/lib/python3.8/site-packages/wandb/filesync/upload_job.py", line 57, in run
    self.push()
  File "/home/huseyin/.local/lib/python3.8/site-packages/wandb/filesync/upload_job.py", line 106, in push
    _, upload_headers, result = self._api.upload_urls(project, [self.save_name])
  File "/home/huseyin/.local/lib/python3.8/site-packages/wandb/apis/normalize.py", line 73, in wrapper
    raise err
  File "/home/huseyin/.local/lib/python3.8/site-packages/wandb/apis/normalize.py", line 41, in wrapper
    return func(*args, **kwargs)
  File "/home/huseyin/.local/lib/python3.8/site-packages/wandb/sdk/internal/internal_api.py", line 2175, in upload_urls
    query_result = self.gql(
  File "/home/huseyin/.local/lib/python3.8/site-packages/wandb/sdk/internal/internal_api.py", line 338, in gql
    ret = self._retry_gql(
  File "/home/huseyin/.local/lib/python3.8/site-packages/wandb/sdk/lib/retry.py", line 147, in __call__
    retry_timedelta_triggered = check_retry_fn(e)
  File "/home/huseyin/.local/lib/python3.8/site-packages/wandb/util.py", line 906, in no_retry_auth
    raise CommError(
wandb.errors.CommError: It appears that you do not have permission to access the requested resource. Please reach out to the project owner to grant you access. If you have the correct permissions, verify that there are no issues with your networking setup.(Error 404: Not Found)
2024-03-13 00:07:20,073 INFO    Thread-11 :2550 [sender.py:transition_state():613] send defer: 11
2024-03-13 00:07:20,073 DEBUG   HandlerThread:2550 [handler.py:handle_request():146] handle_request: defer
2024-03-13 00:07:20,074 INFO    HandlerThread:2550 [handler.py:handle_request_defer():172] handle defer: 11
2024-03-13 00:07:20,075 DEBUG   SenderThread:2550 [sender.py:send_request():407] send_request: defer
2024-03-13 00:07:20,075 INFO    SenderThread:2550 [sender.py:send_request_defer():609] handle sender defer: 11
2024-03-13 00:07:20,076 INFO    SenderThread:2550 [file_pusher.py:join():181] waiting for file pusher
2024-03-13 00:07:20,076 INFO    SenderThread:2550 [sender.py:transition_state():613] send defer: 12
2024-03-13 00:07:20,076 DEBUG   HandlerThread:2550 [handler.py:handle_request():146] handle_request: defer
2024-03-13 00:07:20,076 INFO    HandlerThread:2550 [handler.py:handle_request_defer():172] handle defer: 12
2024-03-13 00:07:20,077 DEBUG   SenderThread:2550 [sender.py:send_request():407] send_request: defer
2024-03-13 00:07:20,077 INFO    SenderThread:2550 [sender.py:send_request_defer():609] handle sender defer: 12
2024-03-13 00:07:20,078 INFO    SenderThread:2550 [file_stream.py:finish():595] file stream finish called
2024-03-13 00:07:20,250 ERROR   FileStreamThread:2550 [file_stream.py:_handle_response():504] dropped chunk 404 Client Error: Not Found for url: https://api.wandb.ai/files/hkaraca/dimchange2/tirrr1qg/file_stream
NoneType: None
2024-03-13 00:07:20,428 INFO    SenderThread:2550 [file_stream.py:finish():599] file stream finish is done
2024-03-13 00:07:20,428 INFO    SenderThread:2550 [sender.py:transition_state():613] send defer: 13
2024-03-13 00:07:20,429 DEBUG   HandlerThread:2550 [handler.py:handle_request():146] handle_request: defer
2024-03-13 00:07:20,429 INFO    HandlerThread:2550 [handler.py:handle_request_defer():172] handle defer: 13
2024-03-13 00:07:20,429 DEBUG   SenderThread:2550 [sender.py:send_request():407] send_request: defer
2024-03-13 00:07:20,429 INFO    SenderThread:2550 [sender.py:send_request_defer():609] handle sender defer: 13
2024-03-13 00:07:20,430 INFO    SenderThread:2550 [sender.py:transition_state():613] send defer: 14
2024-03-13 00:07:20,430 DEBUG   HandlerThread:2550 [handler.py:handle_request():146] handle_request: defer
2024-03-13 00:07:20,431 DEBUG   SenderThread:2550 [sender.py:send():380] send: final
2024-03-13 00:07:20,431 INFO    HandlerThread:2550 [handler.py:handle_request_defer():172] handle defer: 14
2024-03-13 00:07:20,431 DEBUG   SenderThread:2550 [sender.py:send():380] send: footer
2024-03-13 00:07:20,431 DEBUG   SenderThread:2550 [sender.py:send_request():407] send_request: defer
2024-03-13 00:07:20,432 INFO    SenderThread:2550 [sender.py:send_request_defer():609] handle sender defer: 14
2024-03-13 00:07:20,432 DEBUG   HandlerThread:2550 [handler.py:handle_request():146] handle_request: poll_exit
2024-03-13 00:07:20,433 DEBUG   SenderThread:2550 [sender.py:send_request():407] send_request: poll_exit
2024-03-13 00:07:20,434 DEBUG   HandlerThread:2550 [handler.py:handle_request():146] handle_request: server_info
2024-03-13 00:07:20,434 DEBUG   SenderThread:2550 [sender.py:send_request():407] send_request: server_info
2024-03-13 00:07:20,440 DEBUG   HandlerThread:2550 [handler.py:handle_request():146] handle_request: get_summary
2024-03-13 00:07:20,441 DEBUG   HandlerThread:2550 [handler.py:handle_request():146] handle_request: sampled_history
2024-03-13 00:07:20,442 DEBUG   HandlerThread:2550 [handler.py:handle_request():146] handle_request: internal_messages
2024-03-13 00:07:20,443 DEBUG   HandlerThread:2550 [handler.py:handle_request():146] handle_request: job_info
2024-03-13 00:07:20,644 DEBUG   SenderThread:2550 [sender.py:send_request():407] send_request: job_info
2024-03-13 00:07:20,644 INFO    MainThread:2550 [wandb_run.py:_footer_history_summary_info():3599] rendering history
2024-03-13 00:07:20,644 INFO    MainThread:2550 [wandb_run.py:_footer_history_summary_info():3631] rendering summary
2024-03-13 00:07:20,644 INFO    MainThread:2550 [wandb_run.py:_footer_sync_info():3558] logging synced files
2024-03-13 00:07:20,645 DEBUG   HandlerThread:2550 [handler.py:handle_request():146] handle_request: shutdown
2024-03-13 00:07:20,645 INFO    HandlerThread:2550 [handler.py:finish():866] shutting down handler
2024-03-13 00:07:21,093 WARNING StreamThr :2550 [internal.py:is_dead():414] Internal process exiting, parent pid 2535 disappeared
2024-03-13 00:07:21,094 ERROR   StreamThr :2550 [internal.py:wandb_internal():152] Internal process shutdown.
2024-03-13 00:07:21,444 INFO    WriterThread:2550 [datastore.py:close():294] close: /home/huseyin/fungtion/dannpy_yeniden/DANN_py3/wandb/run-20240313_000543-tirrr1qg/run-tirrr1qg.wandb
2024-03-13 00:07:21,644 INFO    SenderThread:2550 [sender.py:finish():1534] shutting down sender
2024-03-13 00:07:21,644 INFO    SenderThread:2550 [file_pusher.py:finish():175] shutting down file pusher
2024-03-13 00:07:21,644 INFO    SenderThread:2550 [file_pusher.py:join():181] waiting for file pusher
