
ms: 0.01 | Mt: 1 | dcm: 7.00 | layer: 2 | Epoch: 0/100
Accuracy of the mnist dataset: 0.290100
Accuracy of the mnist_m dataset: 0.139873
ms: 0.01 | Mt: 1 | dcm: 7.00 | layer: 2 | Epoch: 1/100
Accuracy of the mnist dataset: 0.398000
Accuracy of the mnist_m dataset: 0.134541
Traceback (most recent call last):
  File "/home/huseyin/anaconda3/envs/dannpy5/lib/python3.8/site-packages/torch/serialization.py", line 364, in save
    _save(obj, opened_zipfile, pickle_module, pickle_protocol)
  File "/home/huseyin/anaconda3/envs/dannpy5/lib/python3.8/site-packages/torch/serialization.py", line 483, in _save
    zip_file.write_record(name, buf_value, len(buf_value))
KeyboardInterrupt
During handling of the above exception, another exception occurred:
Traceback (most recent call last):
  File "main.py", line 211, in <module>
    torch.save(my_net, '{0}/mnist_mnistm_model_epoch_current.pth'.format(model_root))
  File "/home/huseyin/anaconda3/envs/dannpy5/lib/python3.8/site-packages/torch/serialization.py", line 365, in save
    return
  File "/home/huseyin/anaconda3/envs/dannpy5/lib/python3.8/site-packages/torch/serialization.py", line 258, in __exit__
    self.file_like.write_end_of_file()
RuntimeError: [enforce fail at inline_container.cc:262] . unexpected pos 2770176 vs 2770064